Workbook
Name AWS_Shared_Pct: Assumptions!$B$12
Name Departments_Table: 'Data Dictionary'!$A$14:$C$20
Name InsureSight_Split: Assumptions!$B$6
Name Products_Table: 'Data Dictionary'!$A$6:$D$9
Name Revenue_Share_Pct_iGO: Assumptions!$B$8
Name Vendors_Table: 'Data Dictionary'!$A$40:$D$54

Sheet CrossfireHiddenWorksheet
A1: ID | B1: Date | C1: Department | D1: Product | E1: Expense Category | F1: Vendor | G1: Amount
A2: c15c63af-93b1-46c7-8644-3820dad92ebe | B2: 7/13/2025 | C2: R&D | D2: DocFast | E2: Connectivity Charges | F2: Salesforce Inc. | G2: 14607.17
A3: 8a85fdcf-6ebb-4953-b8da-7162bdf9a3d5 | B3: 08/23/2025 | C3: Partners | D3: InsureSight | E3: Overhead Allocation & Chargebacks | F3: Palo Alto Networks | G3: 12027.16
A4: c8a310f7-0591-4f07-993b-442ed4044da5 | B4: 2025-12-14 | C4: NetOps | D4: DocFast | E4: Other | F4: Microsoft Corp. | G4: 2747.82
A5: 69e58234-9c0b-4205-8df2-6c9fb98fb403 | B5: 45788 | C5: NetOps | D5: iGO | E5: AWS | F5: Deloitte Consulting | G5: 4469.82
A6: 4722607f-0537-44bf-9194-320a67cfcac4 | B6: 45889 | C6: R&D | D6: DocFast | E6: Advertising and Promotion Expense | F6: Iron Mountain | G6: 6686.43
A7: ce278d40-1e9d-4d2e-9373-fa1300bc4c3a | B7: 45871 | C7: R&D | D7: InsureSight | E7: Other | F7: Zendesk Inc. | G7: 4154.6
A8: 967517e0-f2d6-4f2a-84dc-911fa2893d68 | B8: 45660 | C8: R&D | D8: DocFast | E8: AWS | F8: Cognizant Technology | G8: 12026.38
A9: 2bd05c39-f827-4f27-9e3e-fc6ad796018b | B9: 45967 | C9: NetOps | D9: Affirm | E9: Other | F9: Deloitte Consulting | G9: 11730.61
A10: cde97481-ee1b-4ab4-9d65-3621e2ce790a | B10: 45662 | C10: NetOps | D10: Affirm | E10: Reselling Expenses | F10: Salesforce Inc. | G10: 5464.15
A11: c83d288d-09e6-43dd-b598-4fbc1ab163e7 | B11: 45932 | C11: Content | D11: Affirm | E11: Reselling Expenses | F11: Accenture LLP | G11: 14234.91
A12: c7c3d879-f4ea-42fe-8689-04637efe504b | B12: 45823 | C12: Product Management | D12: iGO | E12: Other | F12: Datadog Inc. | G12: 7965.43
A13: e36d0d88-4984-4c14-a188-4d0fbb5660b6 | B13: 45849 | C13: R&D | D13: InsureSight | E13: Software and Maintenance Expense | F13: Cloudflare Inc. | G13: 437.4
A14: 53eb0a32-96ae-4a39-9676-5bb87485f3fb | B14: 45732 | C14: Content | D14: DocFast | E14: Overhead Allocation & Chargebacks | F14: Cloudflare Inc. | G14: 3963.56
A15: b694b8c0-ad82-4b3c-b286-f4646bd17732 | B15: 45800 | C15: Partners | D15: Affirm | E15: Other | F15: Palo Alto Networks | G15: 10425.01
A16: 7af83a40-5271-4700-a4c8-f992eb7cd1bd | B16: 45876 | C16: NetOps | D16: Affirm | E16: Professional Fees and Outsourcing Expenses | F16: Accenture LLP | G16: 2631.21
... A64: 4596d386-69da-454d-9d57-1a3ecc03ac5b | B64: 46000 | C64: Support | D64: iGO | E64: Other | F64: Deloitte Consulting | G64: 8170.7
A65: ddedef0a-7dd1-4249-835b-5e50f49ff792 | B65: 45865 | C65: Support | D65: Affirm | E65: Data Center Fees | F65: Amazon Web Services | G65: 4350.07
A66: 203c77e4-22ab-4ba5-8e21-17a361c28a6c | B66: 45994 | C66: Support | D66: DocFast | E66: Reselling Expenses | F66: Palo Alto Networks | G66: 11222.71
A67: 51e8f173-f795-49b0-8e52-d6cfa8bbc774 | B67: 45754 | C67: Product Management | D67: InsureSight | E67: Overhead Allocation & Chargebacks | F67: Iron Mountain | G67: 4110.74
A68: f055e65a-d4ee-424a-8e6a-ccf0a966085e | B68: 45708 | C68: R&D | D68: Affirm | E68: Software and Maintenance Expense | F68: Amazon Web Services | G68: 10064.02
A69: 06ea6433-87ae-43db-8206-bcbb22cf9a89 | B69: 45908 | C69: R&D | D69: Affirm | E69: Employee Expenses | F69: Cloudflare Inc. | G69: 6228.86
A70: 5975f85b-0ab3-4fa7-b809-862b6c1c2b22 | B70: 46007 | C70: NetOps | D70: Affirm | E70: Employee Expenses | F70: Cognizant Technology | G70: 14669.77
A71: ad812bfa-99b4-45eb-91bf-e78f1dbf9b21 | B71: 45730 | C71: R&D | D71: DocFast | E71: Office Expenses & Rent Allocation | F71: Deloitte Consulting | G71: 3031.87
A72: 5e55d144-0002-4cbe-b42b-5e24286b2fe4 | B72: 45788 | C72: Support | D72: iGO | E72: Professional Fees and Outsourcing Expenses | F72: Deloitte Consulting | G72: 8633.29
A73: 8ecfeee2-4b6b-4b55-8c5e-902f8e83b0c2 | B73: 45924 | C73: R&D | D73: iGO | E73: Advertising and Promotion Expense | F73: Zendesk Inc. | G73: 13239.56
A74: 8b5b8e4d-82e2-4f4b-b46a-a7832229ec93 | B74: 45718 | C74: Product Management | D74: DocFast | E74: Office Expenses & Rent Allocation | F74: Datadog Inc. | G74: 14052.3
A75: dd2d405d-95fa-48cf-b462-f98775d460ec | B75: 45779 | C75: NetOps | D75: InsureSight | E75: Other | F75: WillisTowersWatson | G75: 1654.15
A76: 170d59d3-aea9-44d6-b3ea-bb3fb3e83e55 | B76: 45818 | C76: Partners | D76: DocFast | E76: Advertising and Promotion Expense | F76: Microsoft Corp. | G76: 7587.98
A77: 384c5824-52a4-49c6-bfbe-7887cbfc33e7 | B77: 45784 | C77: Product Management | D77: iGO | E77: AWS | F77: Datadog Inc. | G77: 10980.23
... A140: f7b7696f-78c1-4ed9-822e-3a6ca0d7bbd0 | B140: 45710 | C140: Support | D140: iGO | E140: Advertising and Promotion Expense | F140: Atlassian Inc. | G140: 12763.89
A141: 5dff82f5-122c-474b-b28d-dfb0916fc44e | B141: 45664 | C141: Content | D141: Affirm | E141: Connectivity Charges | F141: Atlassian Inc. | G141: 1200.22
A142: 0681f2d0-e922-44b1-84fb-25a72ad5a95f | B142: 45735 | C142: Security | D142: DocFast | E142: Reselling Expenses | F142: Atlassian Inc. | G142: 8131.41
A143: 978542e6-fdb4-42b9-9198-446cf0b56b06 | B143: 45863 | C143: R&D | D143: Affirm | E143: Professional Fees and Outsourcing Expenses | F143: Cognizant Technology | G143: 11194.58
A144: 23a4c0d1-e0cd-4769-bc09-08ea55184622 | B144: 45810 | C144: NetOps | D144: DocFast | E144: Software and Maintenance Expense | F144: Microsoft Corp. | G144: 1186.47
A145: bb616d7e-3da6-4c64-adc5-24f38fb8dabf | B145: 45955 | C145: Content | D145: DocFast | E145: AWS | F145: Amazon Web Services | G145: 9530.14
A146: f59ee2e0-f6dc-4964-8a8b-7581d5c7eef9 | B146: 45885 | C146: Security | D146: InsureSight | E146: Overhead Allocation & Chargebacks | F146: Zendesk Inc. | G146: 6506.13
A147: 9fdd55d6-212c-42ba-9e8a-c671bfe322a1 | B147: 45980 | C147: R&D | D147: DocFast | E147: Professional Fees and Outsourcing Expenses | F147: Adobe Systems | G147: 9298.31
A148: 72866fa6-69d2-4950-a9d8-35f076cb197c | B148: 45770 | C148: NetOps | D148: iGO | E148: Data Center Fees | F148: Datadog Inc. | G148: 5731
A149: bb6e0962-387a-4751-b9b5-5065412c5f26 | B149: 45966 | C149: R&D | D149: DocFast | E149: AWS | F149: Salesforce Inc. | G149: 1642.94
...

Sheet Assumptions
A1: Keystone BenefitTech, Inc. | D1: Last Updated: 2026-02-28
A2: Assumptions & Driver Table
A4: DRIVER TABLE
A5: Driver Name | B5: Value | C5: Type | D5: Notes
A6: InsureSight Software Split - InsureSight | B6: 0.22 | C6: Percentage | D6: 22% stays on InsureSight (INTENTIONALLY stored as text for demo)
A7: InsureSight Software Split - Other | B7: 0.78 | C7: Percentage | D7: 78% allocated to iGO, DocFast, Content
A8: iGO Revenue Share % | B8: 0.55 | C8: Percentage | D8: iGO share of total subscription + transaction revenue
A9: Affirm Revenue Share % | B9: 0.28 | C9: Percentage | D9: Affirm share of total subscription + transaction revenue
A10: InsureSight Revenue Share % | B10: 0.12 | C10: Percentage | D10: InsureSight share
A11: DocFast Revenue Share % | B11: 0.05 | C11: Percentage | D11: DocFast share
A12: AWS Shared Pool % | B12: 0.3 | C12: Percentage | D12: Percentage of AWS costs in shared pool
A13: AWS Direct % | B13: 0.7 | C13: Percentage | D13: Percentage of AWS costs directly allocated
A14: Monthly Growth Rate Target | B14: 0.02 | C14: Percentage | D14: Target 2% monthly revenue growth
A15: Q4 Seasonality Uplift | B15: 0.05 | C15: Percentage | D15: 5% Q4 revenue uplift
A16: D&A Rate | B16: 0.01 | C16: Percentage | D16: Depreciation & amortization as % of revenue
A17: R&D Capitalization Rate | B17: 0.3 | C17: Percentage | D17: 30% of R&D capitalized
A18: Employee Cost Allocation Base | B18: 1 | C18: Multiplier | D18: 1.0x base for employee cost allocation
A19: Standard Overhead Rate | B19: 500 | C19: Dollar | D19: Monthly overhead allocation per department
A23: ALLOCATION METHODOLOGY
A24: Department | B24: Allocation Methodology
A25: Revenue | B25: Revenue has been scrubbed and reclassified. Monthly journal entries in Intacct ensure revenue is properly allocated to product lines based on contractual terms and billing records.
A26: NetOps | B26: AWS costs are allocated by product line based on the AWS Allocation Tab. Shared AWS costs are distributed by compute share %. Non-AWS costs (employee, vendor) are allocated pro-rata based on subscription + transaction revenue share by product.
A27: Security | B27: All costs allocated based on percentage of subscription + transaction revenue by product line. No direct employee assignment — treated as shared infrastructure cost.
A28: Support | B28: Employee costs allocated by product lines assigned per management direction. Vendor costs tied to specific products. Remainder allocated pro-rata based on employee headcount by product.
A29: Partners | B29: Vendor costs tied to specific products. InsureSight software costs split 22% to InsureSight and 78% allocated to iGO, DocFast, and Content based on user mix driver. Employee costs by assignment.
A30: Content | B30: Employee costs allocated by product assignment. Vendor costs tied to specific products. Remainder allocated pro-rata based on employee headcount.
A31: Pro Services | B31: Same pattern: employee assignment + vendor-tied + prorata remainder based on employee headcount allocation.
A32: R&D | B32: Same pattern: employee assignment + vendor-tied + prorata remainder based on employee headcount allocation. Includes capitalized software development costs.
A33: Product Management | B33: Same pattern: employee assignment + vendor-tied + prorata remainder based on employee headcount allocation.

Sheet Data Dictionary
A1: Keystone BenefitTech, Inc. | E1: Last Updated: 2026-02-28
A2: Data Dictionary
A4: PRODUCTS
A5: Product Code | B5: Product Name | C5: Product Category | D5: Status
A6: PROD-001 | B6: iGO | C6: Subscription | D6: Active
A7: PROD-002 | B7: Affirm | C7: Subscription | D7: Active
A8: PROD-003 | B8: InsureSight | C8: Mixed | D8: Active
A9: PROD-004 | B9: DocFast | C9: Services | D9: Active
A12: DEPARTMENTS
A13: Department Code | B13: Department Name | C13: Cost Type
A14: DEPT-001 | B14: NetOps | C14: Direct
A15: DEPT-002 | B15: Security | C15: Indirect
A16: DEPT-003 | B16: Support | C16: Direct
A17: DEPT-004 | B17: Partners | C17: Direct
A18: DEPT-005 | B18: Content | C18: Direct
A19: DEPT-006 | B19: R&D | C19: Indirect
A20: DEPT-007 | B20: Product Management | C20: Overhead
A23: EXPENSE CATEGORIES
A24: Category Code | B24: Category Name | C24: GL Account Range | D24: Typical Department
A25: EXP-001 | B25: Employee Expenses | C25: 5000-5199 | D25: All
A26: EXP-002 | B26: Professional Fees and Outsourcing Expenses | C26: 5200-5299 | D26: All
A27: EXP-003 | B27: Advertising and Promotion Expense | C27: 5300-5399 | D27: R&D
A28: EXP-004 | B28: Software and Maintenance Expense | C28: 5400-5499 | D28: All
A29: EXP-005 | B29: Data Center Fees | C29: 5500-5549 | D29: NetOps
A30: EXP-006 | B30: AWS | C30: 5550-5599 | D30: NetOps
A31: EXP-007 | B31: Connectivity Charges | C31: 5600-5649 | D31: NetOps
A32: EXP-008 | B32: Office Expenses & Rent Allocation | C32: 5700-5799 | D32: All
A33: EXP-009 | B33: Overhead Allocation & Chargebacks | C33: 5800-5899 | D33: All
A34: EXP-010 | B34: Other | C34: 5900-5999 | D34: All
A35: EXP-011 | B35: Reselling Expenses | C35: 6000-6099 | D35: Partners
A38: VENDORS
A39: Vendor Code | B39: Vendor Name | C39: Primary Department | D39: Primary Product
A40: VEND-001 | B40: Amazon Web Services | C40: NetOps | D40: All
A41: VEND-002 | B41: Cloudflare Inc. | C41: NetOps | D41: All
A42: VEND-003 | B42: Datadog Inc. | C42: NetOps | D42: All
A43: VEND-004 | B43: CrowdStrike Holdings | C43: Security | D43: All
A44: VEND-005 | B44: Palo Alto Networks | C44: Security | D44: All
A45: VEND-006 | B45: Salesforce Inc. | C45: Support | D45: iGO
A46: VEND-007 | B46: Zendesk Inc. | C46: Support | D46: Affirm
A47: VEND-008 | B47: Accenture LLP | C47: R&D | D47: All
...

Sheet AWS Allocation
A1: Keystone BenefitTech, Inc. | F1: Last Updated: 2026-02-28
A2: AWS Cost Allocation Model
A4: SECTION 1: Product Compute Shares
A5: Product | B5: Compute Share % | C5: Monthly AWS Pool ($)
A6: iGO | B6: 0.45 | C6: See Section 2
A7: Affirm | B7: 0.25 | C7: See Section 2
A8: InsureSight | B8: 0.2 | C8: See Section 2
A9: DocFast | B9: 0.1 | C9: See Section 2
A10: Total | B10: =SUM(B6:B9)
A13: SECTION 2: Monthly AWS Cost Pool
A14: Month | B14: Total AWS Cost Pool ($) | C14: Shared AWS % | D14: Direct AWS %
A15: Jan 2025 | B15: 1907.66 | C15: 0.3 | D15: 0.7
A16: Feb 2025 | B16: 1808.49 | C16: 0.3 | D16: 0.7
A17: Mar 2025 | B17: 2120.48 | C17: 0.3 | D17: 0.7
A18: Apr 2025 | B18: 1964.59 | C18: 0.3 | D18: 0.7
A19: May 2025 | B19: 2384.58 | C19: 0.3 | D19: 0.7
A20: Jun 2025 | B20: 2132.02 | C20: 0.3 | D20: 0.7
A21: Jul 2025 | B21: 2218.45 | C21: 0.3 | D21: 0.7
A22: Aug 2025 | B22: 1875.77 | C22: 0.3 | D22: 0.7
A23: Sep 2025 | B23: 2321.08 | C23: 0.3 | D23: 0.7
A24: Oct 2025 | B24: 2094.53 | C24: 0.3 | D24: 0.7
A25: Nov 2025 | B25: 2323.63 | C25: 0.3 | D25: 0.7
A26: Dec 2025 | B26: 2144.44 | C26: 0.3 | D26: 0.7
A29: SECTION 3: Allocated AWS by Product by Month
A30: Month | B30: iGO | C30: Affirm | D30: InsureSight | E30: DocFast | F30: Total
A31: Jan 2025 | B31: =$B$6*$B$15 | C31: =$B$7*$B$15 | D31: =$B$8*$B$15 | E31: =$B$9*$B$15 | F31: =SUM(B31:E31)
A32: Feb 2025 | B32: =$B$6*$B$16 | C32: =$B$7*$B$16 | D32: =$B$8*$B$16 | E32: =$B$9*$B$16 | F32: =SUM(B32:E32)
A33: Mar 2025 | B33: =$B$6*$B$17 | C33: =$B$7*$B$17 | D33: =$B$8*$B$17 | E33: =$B$9*$B$17 | F33: =SUM(B33:E33)
A34: Apr 2025 | B34: =$B$6*$B$18 | C34: =$B$7*$B$18 | D34: =$B$8*$B$18 | E34: =$B$9*$B$18 | F34: =SUM(B34:E34)
A35: May 2025 | B35: =$B$6*$B$19 | C35: =$B$7*$B$19 | D35: =$B$8*$B$19 | E35: =$B$9*$B$19 | F35: =SUM(B35:E35)
A36: Jun 2025 | B36: =$B$6*$B$20 | C36: =$B$7*$B$20 | D36: =$B$8*$B$20 | E36: =$B$9*$B$20 | F36: =SUM(B36:E36)
A37: Jul 2025 | B37: =$B$6*$B$21 | C37: =$B$7*$B$21 | D37: =$B$8*$B$21 | E37: =$B$9*$B$21 | F37: =SUM(B37:E37)
A38: Aug 2025 | B38: =$B$6*$B$22 | C38: =$B$7*$B$22 | D38: =$B$8*$B$22 | E38: =$B$9*$B$22 | F38: =SUM(B38:E38)
A39: Sep 2025 | B39: =$B$6*$B$23 | C39: =$B$7*$B$23 | D39: =$B$8*$B$23 | E39: =$B$9*$B$23 | F39: =SUM(B39:E39)
A40: Oct 2025 | B40: =$B$6*$B$24 | C40: =$B$7*$B$24 | D40: =$B$8*$B$24 | E40: =$B$9*$B$24 | F40: =SUM(B40:E40)
A41: Nov 2025 | B41: =$B$6*$B$25 | C41: =$B$7*$B$25 | D41: =$B$8*$B$25 | E41: =$B$9*$B$25 | F41: =SUM(B41:E41)
A42: Dec 2025 | B42: =$B$6*$B$26 | C42: =$B$7*$B$26 | D42: =$B$8*$B$26 | E42: =$B$9*$B$26 | F42: =SUM(B42:E42)

Sheet Report-->
A1: Keystone BenefitTech, Inc.
A2: P&L Reporting & Allocation Model — FY2025
A3: Last Updated: 2026-02-28
A5: EXECUTIVE SUMMARY
B7: FULL YEAR REVENUE | D7: CONTRIBUTION MARGIN % | F7: TOP PRODUCT BY REVENUE
B8: ='P&L - Monthly Trend'!R7 | D8: ='P&L - Monthly Trend'!R10 | F8: iGO
B10: BEST MONTH (REVENUE) | D10: TOTAL COST OF REVENUE | F10: Q4 vs Q1 REVENUE GROWTH
B11: December | D11: ='P&L - Monthly Trend'!R8 | F11: =('P&L - Monthly Trend'!Q7-'P&L - Monthly Trend'!N7)/'P&L - Monthly Trend'!N7
B12: file:///C:\Users\connor.atlee\Downloads\KeystoneBenefitTech_PL_Model.xlsx
B13: TABLE OF CONTENTS
B14: file:///C:\Users\connor.atlee\Downloads\KeystoneBenefitTech_PL_Model.xlsx
B15: Assumptions & Driver Table
B16: Data Dictionary — Products, Departments, Vendors
B17: AWS Cost Allocation Model
B18: P&L Monthly Trend — Consolidated & By Product
B19: Product Line Summary — Revenue & Expenses
B20: Functional P&L — Monthly Trend by Product
B21: Functional P&L Summary — January 2025
B22: Functional P&L Summary — February 2025
B23: Functional P&L Summary — March 2025
... B26: Reconciliation Checks — Model Health

Sheet P&L - Monthly Trend
A1: Keystone BenefitTech, Inc. | R1: Last Updated: 2026-02-28
A2: P&L - Monthly Trend
A4: Line Item | B4: Jan 2025 | C4: Feb 2025 | D4: Mar 2025 | E4: Apr 2025 | F4: May 2025 | G4: Jun 2025 | H4: Jul 2025 | I4: Aug 2025 | J4: Sep 2025 | K4: Oct 2025 | L4: Nov 2025 | M4: Dec 2025 | N4: Q1 2025 | O4: Q2 2025 | P4: Q3 2025 | Q4: Q4 2025 | R4: 2025 Total
A6: Consolidated
A7: Revenue | B7: =B15+B23+B31+B39 | C7: =C15+C23+C31+C39 | D7: =D15+D23+D31+D39 | E7: =E15+E23+E31+E39 | F7: =F15+F23+F31+F39 | G7: =G15+G23+G31+G39 | H7: =H15+H23+H31+H39 | I7: =I15+I23+I31+I39 | ... R7: =R15+R23+R31+R39
A8: Cost of Revenue | B8: =B16+B24+B32+B40 | C8: =C16+C24+C32+C40 | D8: =D16+D24+D32+D40 | E8: =E16+E24+E32+E40 | F8: =F16+F24+F32+F40 | G8: =G16+G24+G32+G40 | H8: =H16+H24+H32+H40 | I8: =I16+I24+I32+I40 | ... R8: =R16+R24+R32+R40
A9: Contribution Margin $ | B9: =B17+B25+B33+B41 | C9: =C17+C25+C33+C41 | D9: =D17+D25+D33+D41 | E9: =E17+E25+E33+E41 | F9: =F17+F25+F33+F41 | G9: =G17+G25+G33+G41 | H9: =H17+H25+H33+H41 | I9: =I17+I25+I33+I41 | ... R9: =R17+R25+R33+R41
A10: Contribution Margin % | B10: =IFERROR(B9/B7,0) | C10: =IFERROR(C9/C7,0) | D10: =IFERROR(D9/D7,0) | E10: =IFERROR(E9/E7,0) | F10: =IFERROR(F9/F7,0) | G10: =IFERROR(G9/G7,0) | H10: =IFERROR(H9/H7,0) | I10: =IFERROR(I9/I7,0) | ... R10: =IFERROR(R9/R7,0)
A11: Contribution Margin + R&D $ | B11: =B19+B27+B35+B43 | C11: =C19+C27+C35+C43 | D11: =D19+D27+D35+D43 | E11: =E19+E27+E35+E43 | F11: =F19+F27+F35+F43 | G11: =G19+G27+G35+G43 | H11: =H19+H27+H35+H43 | I11: =I19+I27+I35+I43 | ... R11: =R19+R27+R35+R43
A12: Contribution Margin + R&D % | B12: =IFERROR(B11/B7,0) | C12: =IFERROR(C11/C7,0) | D12: =IFERROR(D11/D7,0) | E12: =IFERROR(E11/E7,0) | F12: =IFERROR(F11/F7,0) | G12: =IFERROR(G11/G7,0) | H12: =IFERROR(H11/H7,0) | I12: =IFERROR(I11/I7,0) | ... R12: =IFERROR(R11/R7,0)
A14: iGO
A15: Revenue | B15: ='Functional P&L - Monthly Trend'!B11 | C15: ='Functional P&L - Monthly Trend'!C11 | D15: ='Functional P&L - Monthly Trend'!D11 | E15: ='Functional P&L - Monthly Trend'!E11 | F15: ='Functional P&L - Monthly Trend'!F11 | G15: ='Functional P&L - Monthly Trend'!G11 | H15: ='Functional P&L - Monthly Trend'!H11 | I15: ='Functional P&L - Monthly Trend'!I11 | ... R15: ='Functional P&L - Monthly Trend'!R11
A16: Cost of Revenue | B16: ='Functional P&L - Monthly Trend'!B21 | C16: ='Functional P&L - Monthly Trend'!C21 | D16: ='Functional P&L - Monthly Trend'!D21 | E16: ='Functional P&L - Monthly Trend'!E21 | F16: ='Functional P&L - Monthly Trend'!F21 | G16: ='Functional P&L - Monthly Trend'!G21 | H16: ='Functional P&L - Monthly Trend'!H21 | I16: ='Functional P&L - Monthly Trend'!I21 | ... R16: ='Functional P&L - Monthly Trend'!R21
A17: Contribution Margin $ | B17: ='Functional P&L - Monthly Trend'!B25 | C17: ='Functional P&L - Monthly Trend'!C25 | D17: ='Functional P&L - Monthly Trend'!D25 | E17: ='Functional P&L - Monthly Trend'!E25 | F17: ='Functional P&L - Monthly Trend'!F25 | G17: ='Functional P&L - Monthly Trend'!G25 | H17: ='Functional P&L - Monthly Trend'!H25 | I17: ='Functional P&L - Monthly Trend'!I25 | ... R17: ='Functional P&L - Monthly Trend'!R25
A18: Contribution Margin % | B18: ='Functional P&L - Monthly Trend'!B30 | C18: ='Functional P&L - Monthly Trend'!C30 | D18: ='Functional P&L - Monthly Trend'!D30 | E18: ='Functional P&L - Monthly Trend'!E30 | F18: ='Functional P&L - Monthly Trend'!F30 | G18: ='Functional P&L - Monthly Trend'!G30 | H18: ='Functional P&L - Monthly Trend'!H30 | I18: ='Functional P&L - Monthly Trend'!I30 | ... R18: ='Functional P&L - Monthly Trend'!R30
A19: Contribution Margin + R&D $ | B19: ='Functional P&L - Monthly Trend'!B38 | C19: ='Functional P&L - Monthly Trend'!C38 | D19: ='Functional P&L - Monthly Trend'!D38 | E19: ='Functional P&L - Monthly Trend'!E38 | F19: ='Functional P&L - Monthly Trend'!F38 | G19: ='Functional P&L - Monthly Trend'!G38 | H19: ='Functional P&L - Monthly Trend'!H38 | I19: ='Functional P&L - Monthly Trend'!I38 | ... R19: ='Functional P&L - Monthly Trend'!R38
A20: Contribution Margin + R&D % | B20: ='Functional P&L - Monthly Trend'!B39 | C20: ='Functional P&L - Monthly Trend'!C39 | D20: ='Functional P&L - Monthly Trend'!D39 | E20: ='Functional P&L - Monthly Trend'!E39 | F20: ='Functional P&L - Monthly Trend'!F39 | G20: ='Functional P&L - Monthly Trend'!G39 | H20: ='Functional P&L - Monthly Trend'!H39 | I20: ='Functional P&L - Monthly Trend'!I39 | ... R20: ='Functional P&L - Monthly Trend'!R39
A22: Affirm
A23: Revenue | B23: ='Functional P&L - Monthly Trend'!B47 | C23: ='Functional P&L - Monthly Trend'!C47 | D23: ='Functional P&L - Monthly Trend'!D47 | E23: ='Functional P&L - Monthly Trend'!E47 | F23: ='Functional P&L - Monthly Trend'!F47 | G23: ='Functional P&L - Monthly Trend'!G47 | H23: ='Functional P&L - Monthly Trend'!H47 | I23: ='Functional P&L - Monthly Trend'!I47 | ... R23: ='Functional P&L - Monthly Trend'!R47
A24: Cost of Revenue | B24: ='Functional P&L - Monthly Trend'!B57 | C24: ='Functional P&L - Monthly Trend'!C57 | D24: ='Functional P&L - Monthly Trend'!D57 | E24: ='Functional P&L - Monthly Trend'!E57 | F24: ='Functional P&L - Monthly Trend'!F57 | G24: ='Functional P&L - Monthly Trend'!G57 | H24: ='Functional P&L - Monthly Trend'!H57 | I24: ='Functional P&L - Monthly Trend'!I57 | ... R24: ='Functional P&L - Monthly Trend'!R57
A25: Contribution Margin $ | B25: ='Functional P&L - Monthly Trend'!B61 | C25: ='Functional P&L - Monthly Trend'!C61 | D25: ='Functional P&L - Monthly Trend'!D61 | E25: ='Functional P&L - Monthly Trend'!E61 | F25: ='Functional P&L - Monthly Trend'!F61 | G25: ='Functional P&L - Monthly Trend'!G61 | H25: ='Functional P&L - Monthly Trend'!H61 | I25: ='Functional P&L - Monthly Trend'!I61 | ... R25: ='Functional P&L - Monthly Trend'!R61
A26: Contribution Margin % | B26: ='Functional P&L - Monthly Trend'!B66 | C26: ='Functional P&L - Monthly Trend'!C66 | D26: ='Functional P&L - Monthly Trend'!D66 | E26: ='Functional P&L - Monthly Trend'!E66 | F26: ='Functional P&L - Monthly Trend'!F66 | G26: ='Functional P&L - Monthly Trend'!G66 | H26: ='Functional P&L - Monthly Trend'!H66 | I26: ='Functional P&L - Monthly Trend'!I66 | ... R26: ='Functional P&L - Monthly Trend'!R66
A27: Contribution Margin + R&D $ | B27: ='Functional P&L - Monthly Trend'!B74 | C27: ='Functional P&L - Monthly Trend'!C74 | D27: ='Functional P&L - Monthly Trend'!D74 | E27: ='Functional P&L - Monthly Trend'!E74 | F27: ='Functional P&L - Monthly Trend'!F74 | G27: ='Functional P&L - Monthly Trend'!G74 | H27: ='Functional P&L - Monthly Trend'!H74 | I27: ='Functional P&L - Monthly Trend'!I74 | ... R27: ='Functional P&L - Monthly Trend'!R74
A28: Contribution Margin + R&D % | B28: ='Functional P&L - Monthly Trend'!B75 | C28: ='Functional P&L - Monthly Trend'!C75 | D28: ='Functional P&L - Monthly Trend'!D75 | E28: ='Functional P&L - Monthly Trend'!E75 | F28: ='Functional P&L - Monthly Trend'!F75 | G28: ='Functional P&L - Monthly Trend'!G75 | H28: ='Functional P&L - Monthly Trend'!H75 | I28: ='Functional P&L - Monthly Trend'!I75 | ... R28: ='Functional P&L - Monthly Trend'!R75
A30: InsureSight
A31: Revenue | B31: ='Functional P&L - Monthly Trend'!B83 | C31: ='Functional P&L - Monthly Trend'!C83 | D31: ='Functional P&L - Monthly Trend'!D83 | E31: ='Functional P&L - Monthly Trend'!E83 | F31: ='Functional P&L - Monthly Trend'!F83 | G31: ='Functional P&L - Monthly Trend'!G83 | H31: ='Functional P&L - Monthly Trend'!H83 | I31: ='Functional P&L - Monthly Trend'!I83 | ... R31: ='Functional P&L - Monthly Trend'!R83
A32: Cost of Revenue | B32: ='Functional P&L - Monthly Trend'!B93 | C32: ='Functional P&L - Monthly Trend'!C93 | D32: ='Functional P&L - Monthly Trend'!D93 | E32: ='Functional P&L - Monthly Trend'!E93 | F32: ='Functional P&L - Monthly Trend'!F93 | G32: ='Functional P&L - Monthly Trend'!G93 | H32: ='Functional P&L - Monthly Trend'!H93 | I32: ='Functional P&L - Monthly Trend'!I93 | ... R32: ='Functional P&L - Monthly Trend'!R93
A33: Contribution Margin $ | B33: ='Functional P&L - Monthly Trend'!B97 | C33: ='Functional P&L - Monthly Trend'!C97 | D33: ='Functional P&L - Monthly Trend'!D97 | E33: ='Functional P&L - Monthly Trend'!E97 | F33: ='Functional P&L - Monthly Trend'!F97 | G33: ='Functional P&L - Monthly Trend'!G97 | H33: ='Functional P&L - Monthly Trend'!H97 | I33: ='Functional P&L - Monthly Trend'!I97 | ... R33: ='Functional P&L - Monthly Trend'!R97
A34: Contribution Margin % | B34: ='Functional P&L - Monthly Trend'!B102 | C34: ='Functional P&L - Monthly Trend'!C102 | D34: ='Functional P&L - Monthly Trend'!D102 | E34: ='Functional P&L - Monthly Trend'!E102 | F34: ='Functional P&L - Monthly Trend'!F102 | G34: ='Functional P&L - Monthly Trend'!G102 | H34: ='Functional P&L - Monthly Trend'!H102 | I34: ='Functional P&L - Monthly Trend'!I102 | ... R34: ='Functional P&L - Monthly Trend'!R102
A35: Contribution Margin + R&D $ | B35: ='Functional P&L - Monthly Trend'!B110 | C35: ='Functional P&L - Monthly Trend'!C110 | D35: ='Functional P&L - Monthly Trend'!D110 | E35: ='Functional P&L - Monthly Trend'!E110 | F35: ='Functional P&L - Monthly Trend'!F110 | G35: ='Functional P&L - Monthly Trend'!G110 | H35: ='Functional P&L - Monthly Trend'!H110 | I35: ='Functional P&L - Monthly Trend'!I110 | ... R35: ='Functional P&L - Monthly Trend'!R110
A36: Contribution Margin + R&D % | B36: ='Functional P&L - Monthly Trend'!B111 | C36: ='Functional P&L - Monthly Trend'!C111 | D36: ='Functional P&L - Monthly Trend'!D111 | E36: ='Functional P&L - Monthly Trend'!E111 | F36: ='Functional P&L - Monthly Trend'!F111 | G36: ='Functional P&L - Monthly Trend'!G111 | H36: ='Functional P&L - Monthly Trend'!H111 | I36: ='Functional P&L - Monthly Trend'!I111 | ... R36: ='Functional P&L - Monthly Trend'!R111
A38: DocFast
A39: Revenue | B39: ='Functional P&L - Monthly Trend'!B119 | C39: ='Functional P&L - Monthly Trend'!C119 | D39: ='Functional P&L - Monthly Trend'!D119 | E39: ='Functional P&L - Monthly Trend'!E119 | F39: ='Functional P&L - Monthly Trend'!F119 | G39: ='Functional P&L - Monthly Trend'!G119 | H39: ='Functional P&L - Monthly Trend'!H119 | I39: ='Functional P&L - Monthly Trend'!I119 | ... R39: ='Functional P&L - Monthly Trend'!R119
A40: Cost of Revenue | B40: ='Functional P&L - Monthly Trend'!B129 | C40: ='Functional P&L - Monthly Trend'!C129 | D40: ='Functional P&L - Monthly Trend'!D129 | E40: ='Functional P&L - Monthly Trend'!E129 | F40: ='Functional P&L - Monthly Trend'!F129 | G40: ='Functional P&L - Monthly Trend'!G129 | H40: ='Functional P&L - Monthly Trend'!H129 | I40: ='Functional P&L - Monthly Trend'!I129 | ... R40: ='Functional P&L - Monthly Trend'!R129
A41: Contribution Margin $ | B41: ='Functional P&L - Monthly Trend'!B133 | C41: ='Functional P&L - Monthly Trend'!C133 | D41: ='Functional P&L - Monthly Trend'!D133 | E41: ='Functional P&L - Monthly Trend'!E133 | F41: ='Functional P&L - Monthly Trend'!F133 | G41: ='Functional P&L - Monthly Trend'!G133 | H41: ='Functional P&L - Monthly Trend'!H133 | I41: ='Functional P&L - Monthly Trend'!I133 | ... R41: ='Functional P&L - Monthly Trend'!R133
A42: Contribution Margin % | B42: ='Functional P&L - Monthly Trend'!B138 | C42: ='Functional P&L - Monthly Trend'!C138 | D42: ='Functional P&L - Monthly Trend'!D138 | E42: ='Functional P&L - Monthly Trend'!E138 | F42: ='Functional P&L - Monthly Trend'!F138 | G42: ='Functional P&L - Monthly Trend'!G138 | H42: ='Functional P&L - Monthly Trend'!H138 | I42: ='Functional P&L - Monthly Trend'!I138 | ... R42: ='Functional P&L - Monthly Trend'!R138
A43: Contribution Margin + R&D $ | B43: ='Functional P&L - Monthly Trend'!B146 | C43: ='Functional P&L - Monthly Trend'!C146 | D43: ='Functional P&L - Monthly Trend'!D146 | E43: ='Functional P&L - Monthly Trend'!E146 | F43: ='Functional P&L - Monthly Trend'!F146 | G43: ='Functional P&L - Monthly Trend'!G146 | H43: ='Functional P&L - Monthly Trend'!H146 | I43: ='Functional P&L - Monthly Trend'!I146 | ... R43: ='Functional P&L - Monthly Trend'!R146
A44: Contribution Margin + R&D % | B44: ='Functional P&L - Monthly Trend'!B147 | C44: ='Functional P&L - Monthly Trend'!C147 | D44: ='Functional P&L - Monthly Trend'!D147 | E44: ='Functional P&L - Monthly Trend'!E147 | F44: ='Functional P&L - Monthly Trend'!F147 | G44: ='Functional P&L - Monthly Trend'!G147 | H44: ='Functional P&L - Monthly Trend'!H147 | I44: ='Functional P&L - Monthly Trend'!I147 | ... R44: ='Functional P&L - Monthly Trend'!R147

Sheet Product Line Summary
A1: Keystone BenefitTech, Inc. | R1: Last Updated: 2026-02-28
A2: Product Line Summary — FY2025
A4: Line Item | B4: Jan 2025 | C4: Feb 2025 | D4: Mar 2025 | E4: Apr 2025 | F4: May 2025 | G4: Jun 2025 | H4: Jul 2025 | I4: Aug 2025 | J4: Sep 2025 | K4: Oct 2025 | L4: Nov 2025 | M4: Dec 2025 | N4: Q1 2025 | O4: Q2 2025 | P4: Q3 2025 | Q4: Q4 2025 | R4: 2025 Total
A5: SECTION 1: P&L Summary
A7: iGO
A8: Revenue | B8: ='Functional P&L - Monthly Trend'!B11 | C8: ='Functional P&L - Monthly Trend'!C11 | D8: ='Functional P&L - Monthly Trend'!D11 | E8: ='Functional P&L - Monthly Trend'!E11 | F8: ='Functional P&L - Monthly Trend'!F11 | G8: ='Functional P&L - Monthly Trend'!G11 | H8: ='Functional P&L - Monthly Trend'!H11 | I8: ='Functional P&L - Monthly Trend'!I11 | ... R8: ='Functional P&L - Monthly Trend'!R11
A9: Cost of Revenue | B9: ='Functional P&L - Monthly Trend'!B21 | C9: ='Functional P&L - Monthly Trend'!C21 | D9: ='Functional P&L - Monthly Trend'!D21 | E9: ='Functional P&L - Monthly Trend'!E21 | F9: ='Functional P&L - Monthly Trend'!F21 | G9: ='Functional P&L - Monthly Trend'!G21 | H9: ='Functional P&L - Monthly Trend'!H21 | I9: ='Functional P&L - Monthly Trend'!I21 | ... R9: ='Functional P&L - Monthly Trend'!R21
A10: Contribution Margin $ | B10: ='Functional P&L - Monthly Trend'!B25 | C10: ='Functional P&L - Monthly Trend'!C25 | D10: ='Functional P&L - Monthly Trend'!D25 | E10: ='Functional P&L - Monthly Trend'!E25 | F10: ='Functional P&L - Monthly Trend'!F25 | G10: ='Functional P&L - Monthly Trend'!G25 | H10: ='Functional P&L - Monthly Trend'!H25 | I10: ='Functional P&L - Monthly Trend'!I25 | ... R10: ='Functional P&L - Monthly Trend'!R25
A11: Contribution Margin % | B11: ='Functional P&L - Monthly Trend'!B30 | C11: ='Functional P&L - Monthly Trend'!C30 | D11: ='Functional P&L - Monthly Trend'!D30 | E11: ='Functional P&L - Monthly Trend'!E30 | F11: ='Functional P&L - Monthly Trend'!F30 | G11: ='Functional P&L - Monthly Trend'!G30 | H11: ='Functional P&L - Monthly Trend'!H30 | I11: ='Functional P&L - Monthly Trend'!I30 | ... R11: ='Functional P&L - Monthly Trend'!R30
A12: Contribution Margin + R&D $ | B12: ='Functional P&L - Monthly Trend'!B38 | C12: ='Functional P&L - Monthly Trend'!C38 | D12: ='Functional P&L - Monthly Trend'!D38 | E12: ='Functional P&L - Monthly Trend'!E38 | F12: ='Functional P&L - Monthly Trend'!F38 | G12: ='Functional P&L - Monthly Trend'!G38 | H12: ='Functional P&L - Monthly Trend'!H38 | I12: ='Functional P&L - Monthly Trend'!I38 | ... R12: ='Functional P&L - Monthly Trend'!R38
A13: Contribution Margin + R&D % | B13: ='Functional P&L - Monthly Trend'!B39 | C13: ='Functional P&L - Monthly Trend'!C39 | D13: ='Functional P&L - Monthly Trend'!D39 | E13: ='Functional P&L - Monthly Trend'!E39 | F13: ='Functional P&L - Monthly Trend'!F39 | G13: ='Functional P&L - Monthly Trend'!G39 | H13: ='Functional P&L - Monthly Trend'!H39 | I13: ='Functional P&L - Monthly Trend'!I39 | ... R13: ='Functional P&L - Monthly Trend'!R39
A15: Affirm
A16: Revenue | B16: ='Functional P&L - Monthly Trend'!B47 | C16: ='Functional P&L - Monthly Trend'!C47 | D16: ='Functional P&L - Monthly Trend'!D47 | E16: ='Functional P&L - Monthly Trend'!E47 | F16: ='Functional P&L - Monthly Trend'!F47 | G16: ='Functional P&L - Monthly Trend'!G47 | H16: ='Functional P&L - Monthly Trend'!H47 | I16: ='Functional P&L - Monthly Trend'!I47 | ... R16: ='Functional P&L - Monthly Trend'!R47
A17: Cost of Revenue | B17: ='Functional P&L - Monthly Trend'!B57 | C17: ='Functional P&L - Monthly Trend'!C57 | D17: ='Functional P&L - Monthly Trend'!D57 | E17: ='Functional P&L - Monthly Trend'!E57 | F17: ='Functional P&L - Monthly Trend'!F57 | G17: ='Functional P&L - Monthly Trend'!G57 | H17: ='Functional P&L - Monthly Trend'!H57 | I17: ='Functional P&L - Monthly Trend'!I57 | ... R17: ='Functional P&L - Monthly Trend'!R57
A18: Contribution Margin $ | B18: ='Functional P&L - Monthly Trend'!B61 | C18: ='Functional P&L - Monthly Trend'!C61 | D18: ='Functional P&L - Monthly Trend'!D61 | E18: ='Functional P&L - Monthly Trend'!E61 | F18: ='Functional P&L - Monthly Trend'!F61 | G18: ='Functional P&L - Monthly Trend'!G61 | H18: ='Functional P&L - Monthly Trend'!H61 | I18: ='Functional P&L - Monthly Trend'!I61 | ... R18: ='Functional P&L - Monthly Trend'!R61
A19: Contribution Margin % | B19: ='Functional P&L - Monthly Trend'!B66 | C19: ='Functional P&L - Monthly Trend'!C66 | D19: ='Functional P&L - Monthly Trend'!D66 | E19: ='Functional P&L - Monthly Trend'!E66 | F19: ='Functional P&L - Monthly Trend'!F66 | G19: ='Functional P&L - Monthly Trend'!G66 | H19: ='Functional P&L - Monthly Trend'!H66 | I19: ='Functional P&L - Monthly Trend'!I66 | ... R19: ='Functional P&L - Monthly Trend'!R66
A20: Contribution Margin + R&D $ | B20: ='Functional P&L - Monthly Trend'!B74 | C20: ='Functional P&L - Monthly Trend'!C74 | D20: ='Functional P&L - Monthly Trend'!D74 | E20: ='Functional P&L - Monthly Trend'!E74 | F20: ='Functional P&L - Monthly Trend'!F74 | G20: ='Functional P&L - Monthly Trend'!G74 | H20: ='Functional P&L - Monthly Trend'!H74 | I20: ='Functional P&L - Monthly Trend'!I74 | ... R20: ='Functional P&L - Monthly Trend'!R74
A21: Contribution Margin + R&D % | B21: ='Functional P&L - Monthly Trend'!B75 | C21: ='Functional P&L - Monthly Trend'!C75 | D21: ='Functional P&L - Monthly Trend'!D75 | E21: ='Functional P&L - Monthly Trend'!E75 | F21: ='Functional P&L - Monthly Trend'!F75 | G21: ='Functional P&L - Monthly Trend'!G75 | H21: ='Functional P&L - Monthly Trend'!H75 | I21: ='Functional P&L - Monthly Trend'!I75 | ... R21: ='Functional P&L - Monthly Trend'!R75
A23: Insuresight
A24: Revenue | B24: ='Functional P&L - Monthly Trend'!B83 | C24: ='Functional P&L - Monthly Trend'!C83 | D24: ='Functional P&L - Monthly Trend'!D83 | E24: ='Functional P&L - Monthly Trend'!E83 | F24: ='Functional P&L - Monthly Trend'!F83 | G24: ='Functional P&L - Monthly Trend'!G83 | H24: ='Functional P&L - Monthly Trend'!H83 | I24: ='Functional P&L - Monthly Trend'!I83 | ... R24: ='Functional P&L - Monthly Trend'!R83
A25: Cost of Revenue | B25: ='Functional P&L - Monthly Trend'!B93 | C25: ='Functional P&L - Monthly Trend'!C93 | D25: ='Functional P&L - Monthly Trend'!D93 | E25: ='Functional P&L - Monthly Trend'!E93 | F25: ='Functional P&L - Monthly Trend'!F93 | G25: ='Functional P&L - Monthly Trend'!G93 | H25: ='Functional P&L - Monthly Trend'!H93 | I25: ='Functional P&L - Monthly Trend'!I93 | ... R25: ='Functional P&L - Monthly Trend'!R93
A26: Contribution Margin $ | B26: ='Functional P&L - Monthly Trend'!B97 | C26: ='Functional P&L - Monthly Trend'!C97 | D26: ='Functional P&L - Monthly Trend'!D97 | E26: ='Functional P&L - Monthly Trend'!E97 | F26: ='Functional P&L - Monthly Trend'!F97 | G26: ='Functional P&L - Monthly Trend'!G97 | H26: ='Functional P&L - Monthly Trend'!H97 | I26: ='Functional P&L - Monthly Trend'!I97 | ... R26: ='Functional P&L - Monthly Trend'!R97
A27: Contribution Margin % | B27: ='Functional P&L - Monthly Trend'!B102 | C27: ='Functional P&L - Monthly Trend'!C102 | D27: ='Functional P&L - Monthly Trend'!D102 | E27: ='Functional P&L - Monthly Trend'!E102 | F27: ='Functional P&L - Monthly Trend'!F102 | G27: ='Functional P&L - Monthly Trend'!G102 | H27: ='Functional P&L - Monthly Trend'!H102 | I27: ='Functional P&L - Monthly Trend'!I102 | ... R27: ='Functional P&L - Monthly Trend'!R102
A28: Contribution Margin + R&D $ | B28: ='Functional P&L - Monthly Trend'!B110 | C28: ='Functional P&L - Monthly Trend'!C110 | D28: ='Functional P&L - Monthly Trend'!D110 | E28: ='Functional P&L - Monthly Trend'!E110 | F28: ='Functional P&L - Monthly Trend'!F110 | G28: ='Functional P&L - Monthly Trend'!G110 | H28: ='Functional P&L - Monthly Trend'!H110 | I28: ='Functional P&L - Monthly Trend'!I110 | ... R28: ='Functional P&L - Monthly Trend'!R110
A29: Contribution Margin + R&D % | B29: ='Functional P&L - Monthly Trend'!B111 | C29: ='Functional P&L - Monthly Trend'!C111 | D29: ='Functional P&L - Monthly Trend'!D111 | E29: ='Functional P&L - Monthly Trend'!E111 | F29: ='Functional P&L - Monthly Trend'!F111 | G29: ='Functional P&L - Monthly Trend'!G111 | H29: ='Functional P&L - Monthly Trend'!H111 | I29: ='Functional P&L - Monthly Trend'!I111 | ... R29: ='Functional P&L - Monthly Trend'!R111
A31: DocFast
A32: Revenue | B32: ='Functional P&L - Monthly Trend'!B119 | C32: ='Functional P&L - Monthly Trend'!C119 | D32: ='Functional P&L - Monthly Trend'!D119 | E32: ='Functional P&L - Monthly Trend'!E119 | F32: ='Functional P&L - Monthly Trend'!F119 | G32: ='Functional P&L - Monthly Trend'!G119 | H32: ='Functional P&L - Monthly Trend'!H119 | I32: ='Functional P&L - Monthly Trend'!I119 | ... R32: ='Functional P&L - Monthly Trend'!R119
A33: Cost of Revenue | B33: ='Functional P&L - Monthly Trend'!B129 | C33: ='Functional P&L - Monthly Trend'!C129 | D33: ='Functional P&L - Monthly Trend'!D129 | E33: ='Functional P&L - Monthly Trend'!E129 | F33: ='Functional P&L - Monthly Trend'!F129 | G33: ='Functional P&L - Monthly Trend'!G129 | H33: ='Functional P&L - Monthly Trend'!H129 | I33: ='Functional P&L - Monthly Trend'!I129 | ... R33: ='Functional P&L - Monthly Trend'!R129
A34: Contribution Margin $ | B34: ='Functional P&L - Monthly Trend'!B133 | C34: ='Functional P&L - Monthly Trend'!C133 | D34: ='Functional P&L - Monthly Trend'!D133 | E34: ='Functional P&L - Monthly Trend'!E133 | F34: ='Functional P&L - Monthly Trend'!F133 | G34: ='Functional P&L - Monthly Trend'!G133 | H34: ='Functional P&L - Monthly Trend'!H133 | I34: ='Functional P&L - Monthly Trend'!I133 | ... R34: ='Functional P&L - Monthly Trend'!R133
A35: Contribution Margin % | B35: ='Functional P&L - Monthly Trend'!B138 | C35: ='Functional P&L - Monthly Trend'!C138 | D35: ='Functional P&L - Monthly Trend'!D138 | E35: ='Functional P&L - Monthly Trend'!E138 | F35: ='Functional P&L - Monthly Trend'!F138 | G35: ='Functional P&L - Monthly Trend'!G138 | H35: ='Functional P&L - Monthly Trend'!H138 | I35: ='Functional P&L - Monthly Trend'!I138 | ... R35: ='Functional P&L - Monthly Trend'!R138
A36: Contribution Margin + R&D $ | B36: ='Functional P&L - Monthly Trend'!B146 | C36: ='Functional P&L - Monthly Trend'!C146 | D36: ='Functional P&L - Monthly Trend'!D146 | E36: ='Functional P&L - Monthly Trend'!E146 | F36: ='Functional P&L - Monthly Trend'!F146 | G36: ='Functional P&L - Monthly Trend'!G146 | H36: ='Functional P&L - Monthly Trend'!H146 | I36: ='Functional P&L - Monthly Trend'!I146 | ... R36: ='Functional P&L - Monthly Trend'!R146
A37: Contribution Margin + R&D % | B37: ='Functional P&L - Monthly Trend'!B147 | C37: ='Functional P&L - Monthly Trend'!C147 | D37: ='Functional P&L - Monthly Trend'!D147 | E37: ='Functional P&L - Monthly Trend'!E147 | F37: ='Functional P&L - Monthly Trend'!F147 | G37: ='Functional P&L - Monthly Trend'!G147 | H37: ='Functional P&L - Monthly Trend'!H147 | I37: ='Functional P&L - Monthly Trend'!I147 | ... R37: ='Functional P&L - Monthly Trend'!R147
A40: SECTION 2: Expenses by Department
A42: iGO
A43: NetOps | B43: ='Functional P&L - Monthly Trend'!B14 | C43: ='Functional P&L - Monthly Trend'!C14 | D43: ='Functional P&L - Monthly Trend'!D14 | E43: ='Functional P&L - Monthly Trend'!E14 | F43: ='Functional P&L - Monthly Trend'!F14 | G43: ='Functional P&L - Monthly Trend'!G14 | H43: ='Functional P&L - Monthly Trend'!H14 | I43: ='Functional P&L - Monthly Trend'!I14 | ... R43: ='Functional P&L - Monthly Trend'!R14
A44: Security | B44: ='Functional P&L - Monthly Trend'!B15 | C44: ='Functional P&L - Monthly Trend'!C15 | D44: ='Functional P&L - Monthly Trend'!D15 | E44: ='Functional P&L - Monthly Trend'!E15 | F44: ='Functional P&L - Monthly Trend'!F15 | G44: ='Functional P&L - Monthly Trend'!G15 | H44: ='Functional P&L - Monthly Trend'!H15 | I44: ='Functional P&L - Monthly Trend'!I15 | ... R44: ='Functional P&L - Monthly Trend'!R15
A45: Support | B45: ='Functional P&L - Monthly Trend'!B16 | C45: ='Functional P&L - Monthly Trend'!C16 | D45: ='Functional P&L - Monthly Trend'!D16 | E45: ='Functional P&L - Monthly Trend'!E16 | F45: ='Functional P&L - Monthly Trend'!F16 | G45: ='Functional P&L - Monthly Trend'!G16 | H45: ='Functional P&L - Monthly Trend'!H16 | I45: ='Functional P&L - Monthly Trend'!I16 | ... R45: ='Functional P&L - Monthly Trend'!R16
A46: Partners | B46: ='Functional P&L - Monthly Trend'!B17 | C46: ='Functional P&L - Monthly Trend'!C17 | D46: ='Functional P&L - Monthly Trend'!D17 | E46: ='Functional P&L - Monthly Trend'!E17 | F46: ='Functional P&L - Monthly Trend'!F17 | G46: ='Functional P&L - Monthly Trend'!G17 | H46: ='Functional P&L - Monthly Trend'!H17 | I46: ='Functional P&L - Monthly Trend'!I17 | ... R46: ='Functional P&L - Monthly Trend'!R17
A47: Content | B47: ='Functional P&L - Monthly Trend'!B18 | C47: ='Functional P&L - Monthly Trend'!C18 | D47: ='Functional P&L - Monthly Trend'!D18 | E47: ='Functional P&L - Monthly Trend'!E18 | F47: ='Functional P&L - Monthly Trend'!F18 | G47: ='Functional P&L - Monthly Trend'!G18 | H47: ='Functional P&L - Monthly Trend'!H18 | I47: ='Functional P&L - Monthly Trend'!I18 | ... R47: ='Functional P&L - Monthly Trend'!R18
A48: Research & Development | B48: ='Functional P&L - Monthly Trend'!B33 | C48: ='Functional P&L - Monthly Trend'!C33 | D48: ='Functional P&L - Monthly Trend'!D33 | E48: ='Functional P&L - Monthly Trend'!E33 | F48: ='Functional P&L - Monthly Trend'!F33 | G48: ='Functional P&L - Monthly Trend'!G33 | H48: ='Functional P&L - Monthly Trend'!H33 | I48: ='Functional P&L - Monthly Trend'!I33 | ... R48: ='Functional P&L - Monthly Trend'!R33
...

Sheet Functional P&L - Monthly Trend
A1: Keystone BenefitTech, Inc. | R1: Last Updated: 2026-02-28
A2: Functional P&L - Monthly Trend
A4: Line Item | B4: Jan 2025 | C4: Feb 2025 | D4: Mar 2025 | E4: Apr 2025 | F4: May 2025 | G4: Jun 2025 | H4: Jul 2025 | I4: Aug 2025 | J4: Sep 2025 | K4: Oct 2025 | L4: Nov 2025 | M4: Dec 2025 | N4: Q1 2025 | O4: Q2 2025 | P4: Q3 2025 | Q4: Q4 2025 | R4: 2025 Total
A6: iGO
A7: Revenue
A8: Subscription | B8: 4040.8 | C8: 4245.3 | D8: 4346.38 | E8: 4387.97 | F8: 4232.75 | G8: 4490.3 | H8: 4509.14 | I8: 4704.67 | J8: 4511.68 | K8: 4896.07 | L8: 5126.58 | M8: 5003.52 | N8: =SUM(B8:D8) | O8: =SUM(E8:G8) | P8: =SUM(H8:J8) | Q8: =SUM(K8:M8) | R8: =SUM(B8:M8)
A9: Transactions | B9: 1010.1 | C9: 880.75 | D9: 904.62 | E9: 1045.58 | F9: 997.55 | G9: 921.82 | H9: 1007.2 | I9: 1047.57 | J9: 1007.15 | K9: 1253.63 | L9: 1213.96 | M9: 1022.47 | N9: =SUM(B9:D9) | O9: =SUM(E9:G9) | P9: =SUM(H9:J9) | Q9: =SUM(K9:M9) | R9: =SUM(B9:M9)
A10: Services | B10: 317.61 | C10: 360.3 | D10: 505.57 | E10: 223.73 | F10: 451.84 | G10: 492.68 | H10: 353.98 | I10: 366.22 | J10: 661.31 | K10: 548.31 | L10: 283.49 | M10: 686.76 | N10: =SUM(B10:D10) | O10: =SUM(E10:G10) | P10: =SUM(H10:J10) | Q10: =SUM(K10:M10) | R10: =SUM(B10:M10)
A11: Revenue | B11: =B8+B9+B10 | C11: =C8+C9+C10 | D11: =D8+D9+D10 | E11: =E8+E9+E10 | F11: =F8+F9+F10 | G11: =G8+G9+G10 | H11: =H8+H9+H10 | I11: =I8+I9+I10 | ... M11: =M8+M9+M10 | N11: =SUM(B11:D11) | O11: =SUM(E11:G11) | P11: =SUM(H11:J11) | Q11: =SUM(K11:M11) | R11: =SUM(B11:M11)
A13: Cost of Revenue
A14: NetOps | B14: 726.3 | C14: 742.28 | D14: 774.61 | E14: 754.97 | F14: 752.67 | G14: 847.48 | H14: 792.59 | I14: 870.9 | J14: 808.45 | K14: 874.51 | L14: 964.98 | M14: 945.25 | N14: =SUM(B14:D14) | O14: =SUM(E14:G14) | P14: =SUM(H14:J14) | Q14: =SUM(K14:M14) | R14: =SUM(B14:M14)
A15: Security | B15: 162.53 | C15: 173.52 | D15: 167.85 | E15: 171.95 | F15: 177.25 | G15: 181.03 | H15: 181.13 | I15: 192.85 | J15: 172.48 | K15: 197.49 | L15: 205.12 | M15: 207.2 | N15: =SUM(B15:D15) | O15: =SUM(E15:G15) | P15: =SUM(H15:J15) | Q15: =SUM(K15:M15) | R15: =SUM(B15:M15)
A16: Support | B16: 234.14 | C16: 266.45 | D16: 249.83 | E16: 255.01 | F16: 256.38 | G16: 274.14 | H16: 263.38 | I16: 271.55 | J16: 281.27 | K16: 286.31 | L16: 310.5 | M16: 303.8 | N16: =SUM(B16:D16) | O16: =SUM(E16:G16) | P16: =SUM(H16:J16) | Q16: =SUM(K16:M16) | R16: =SUM(B16:M16)
A17: Partners | B17: 120.24 | C17: 128.42 | D17: 130.69 | E17: 137.36 | F17: 123.23 | G17: 137.62 | H17: 131.74 | I17: 139.67 | J17: 137.67 | K17: 143.94 | L17: 150.97 | M17: 153.89 | N17: =SUM(B17:D17) | O17: =SUM(E17:G17) | P17: =SUM(H17:J17) | Q17: =SUM(K17:M17) | R17: =SUM(B17:M17)
A18: Content | B18: 19.34 | C18: 21.14 | D18: 22.82 | E18: 23.03 | F18: 20.26 | G18: 21.81 | H18: 22.02 | I18: 24.54 | J18: 23.42 | K18: 25.41 | L18: 25.3 | M18: 24.16 | N18: =SUM(B18:D18) | O18: =SUM(E18:G18) | P18: =SUM(H18:J18) | Q18: =SUM(K18:M18) | R18: =SUM(B18:M18)
A19: Cost of Subscription | B19: =SUM(B14:B18) | C19: =SUM(C14:C18) | D19: =SUM(D14:D18) | E19: =SUM(E14:E18) | F19: =SUM(F14:F18) | G19: =SUM(G14:G18) | H19: =SUM(H14:H18) | I19: =SUM(I14:I18) | ... M19: =SUM(M14:M18) | N19: =SUM(B19:D19) | O19: =SUM(E19:G19) | P19: =SUM(H19:J19) | Q19: =SUM(K19:M19) | R19: =SUM(B19:M19)
A20: Cost of Services | B20: 186.35 | C20: 204.27 | D20: 287.15 | E20: 113.38 | F20: 259.33 | G20: 270.35 | H20: 191.71 | I20: 206.94 | J20: 358.46 | K20: 325.93 | L20: 144.95 | M20: 400.09 | N20: =SUM(B20:D20) | O20: =SUM(E20:G20) | P20: =SUM(H20:J20) | Q20: =SUM(K20:M20) | R20: =SUM(B20:M20)
A21: Cost of Revenue | B21: =B19+B20 | C21: =C19+C20 | D21: =D19+D20 | E21: =E19+E20 | F21: =F19+F20 | G21: =G19+G20 | H21: =H19+H20 | I21: =I19+I20 | ... M21: =M19+M20 | N21: =SUM(B21:D21) | O21: =SUM(E21:G21) | P21: =SUM(H21:J21) | Q21: =SUM(K21:M21) | R21: =SUM(B21:M21)
A23: Subscriptions Contribution | B23: =B8-B19 | C23: =C8-C19 | D23: =D8-D19 | E23: =E8-E19 | F23: =F8-F19 | G23: =G8-G19 | H23: =H8-H19 | I23: =I8-I19 | ... M23: =M8-M19 | N23: =SUM(B23:D23) | O23: =SUM(E23:G23) | P23: =SUM(H23:J23) | Q23: =SUM(K23:M23) | R23: =SUM(B23:M23)
A24: Services Contribution | B24: =B10-B20 | C24: =C10-C20 | D24: =D10-D20 | E24: =E10-E20 | F24: =F10-F20 | G24: =G10-G20 | H24: =H10-H20 | I24: =I10-I20 | ... M24: =M10-M20 | N24: =SUM(B24:D24) | O24: =SUM(E24:G24) | P24: =SUM(H24:J24) | Q24: =SUM(K24:M24) | R24: =SUM(B24:M24)
A25: Contribution Margin | B25: =B23+B24 | C25: =C23+C24 | D25: =D23+D24 | E25: =E23+E24 | F25: =F23+F24 | G25: =G23+G24 | H25: =H23+H24 | I25: =I23+I24 | ... M25: =M23+M24 | N25: =SUM(B25:D25) | O25: =SUM(E25:G25) | P25: =SUM(H25:J25) | Q25: =SUM(K25:M25) | R25: =SUM(B25:M25)
A26: D&A | B26: 53.69 | C26: 54.86 | D26: 57.57 | E26: 56.57 | F26: 56.82 | G26: 59.05 | H26: 58.7 | I26: 61.18 | J26: 61.8 | K26: 66.98 | L26: 66.24 | M26: 67.13 | N26: =SUM(B26:D26) | O26: =SUM(E26:G26) | P26: =SUM(H26:J26) | Q26: =SUM(K26:M26) | R26: =SUM(B26:M26)
A27: Contribution Margin GAAP | B27: =B25-B26 | C27: =C25-C26 | D27: =D25-D26 | E27: =E25-E26 | F27: =F25-F26 | G27: =G25-G26 | H27: =H25-H26 | I27: =I25-I26 | ... M27: =M25-M26 | N27: =SUM(B27:D27) | O27: =SUM(E27:G27) | P27: =SUM(H27:J27) | Q27: =SUM(K27:M27) | R27: =SUM(B27:M27)
A28: Subscription Margin % | B28: =IFERROR(B23/B8,0) | C28: =IFERROR(C23/C8,0) | D28: =IFERROR(D23/D8,0) | E28: =IFERROR(E23/E8,0) | F28: =IFERROR(F23/F8,0) | G28: =IFERROR(G23/G8,0) | H28: =IFERROR(H23/H8,0) | I28: =IFERROR(I23/I8,0) | ... R28: =IFERROR(R23/R8,0)
A29: Services Margin % | B29: =IFERROR(B24/B10,0) | C29: =IFERROR(C24/C10,0) | D29: =IFERROR(D24/D10,0) | E29: =IFERROR(E24/E10,0) | F29: =IFERROR(F24/F10,0) | G29: =IFERROR(G24/G10,0) | H29: =IFERROR(H24/H10,0) | I29: =IFERROR(I24/I10,0) | ... R29: =IFERROR(R24/R10,0)
A30: Total Margin % | B30: =IFERROR(B25/B11,0) | C30: =IFERROR(C25/C11,0) | D30: =IFERROR(D25/D11,0) | E30: =IFERROR(E25/E11,0) | F30: =IFERROR(F25/F11,0) | G30: =IFERROR(G25/G11,0) | H30: =IFERROR(H25/H11,0) | I30: =IFERROR(I25/I11,0) | ... R30: =IFERROR(R25/R11,0)
A32: R&D
A33: R&D (includes Cap Software) | B33: 443.47 | C33: 404.34 | D33: 492.87 | E33: 456.44 | F33: 433.01 | G33: 503.02 | H33: 452.84 | I33: 470.83 | J33: 455.62 | K33: 539.75 | L33: 498.33 | M33: 568.01 | N33: =SUM(B33:D33) | O33: =SUM(E33:G33) | P33: =SUM(H33:J33) | Q33: =SUM(K33:M33) | R33: =SUM(B33:M33)
A34: Research & Development | B34: 305.48 | C34: 270.22 | D34: 363.03 | E34: 329.9 | F34: 297.29 | G34: 334.7 | H34: 339.47 | I34: 318.22 | J34: 338.29 | K34: 359.77 | L34: 358.39 | M34: 374.95 | N34: =SUM(B34:D34) | O34: =SUM(E34:G34) | P34: =SUM(H34:J34) | Q34: =SUM(K34:M34) | R34: =SUM(B34:M34)
A35: Capitalized R&D | B35: -137.99 | C35: -134.12 | D35: -129.84 | E35: -126.54 | F35: -135.72 | G35: -168.32 | H35: -113.37 | I35: -152.61 | J35: -117.33 | K35: -179.98 | L35: -139.94 | M35: -193.06 | N35: =SUM(B35:D35) | O35: =SUM(E35:G35) | P35: =SUM(H35:J35) | Q35: =SUM(K35:M35) | R35: =SUM(B35:M35)
A36: Product Management | B36: 176.75 | C36: 157.99 | D36: 159.41 | E36: 173.28 | F36: 162.42 | G36: 162.7 | H36: 185.66 | I36: 185.45 | J36: 199.61 | K36: 204.26 | L36: 214.58 | M36: 189.71 | N36: =SUM(B36:D36) | O36: =SUM(E36:G36) | P36: =SUM(H36:J36) | Q36: =SUM(K36:M36) | R36: =SUM(B36:M36)
A38: Contribution Margin + R&D $ | B38: =B25-B33-B36 | C38: =C25-C33-C36 | D38: =D25-D33-D36 | E38: =E25-E33-E36 | F38: =F25-F33-F36 | G38: =G25-G33-G36 | H38: =H25-H33-H36 | I38: =I25-I33-I36 | ... M38: =M25-M33-M36 | N38: =SUM(B38:D38) | O38: =SUM(E38:G38) | P38: =SUM(H38:J38) | Q38: =SUM(K38:M38) | R38: =SUM(B38:M38)
A39: Contribution Margin + R&D % | B39: =IFERROR(B38/B11,0) | C39: =IFERROR(C38/C11,0) | D39: =IFERROR(D38/D11,0) | E39: =IFERROR(E38/E11,0) | F39: =IFERROR(F38/F11,0) | G39: =IFERROR(G38/G11,0) | H39: =IFERROR(H38/H11,0) | I39: =IFERROR(I38/I11,0) | ... R39: =IFERROR(R38/R11,0)
A42: Affirm
A43: Revenue
A44: Subscription | B44: 2046.95 | C44: 1980.7 | D44: 1979.69 | E44: 2092.06 | F44: 2122.54 | G44: 2127.6 | H44: 2159.9 | I44: 2134.14 | J44: 2105.26 | K44: 2392.87 | L44: 2379.39 | M44: 2405.21 | N44: =SUM(B44:D44) | O44: =SUM(E44:G44) | P44: =SUM(H44:J44) | Q44: =SUM(K44:M44) | R44: =SUM(B44:M44)
A45: Transactions | B45: 496.93 | C45: 457.06 | D45: 486.98 | E45: 422.43 | F45: 484.32 | G45: 529.28 | H45: 455.67 | I45: 505.22 | J45: 462.18 | K45: 540.08 | L45: 540.19 | M45: 519.53 | N45: =SUM(B45:D45) | O45: =SUM(E45:G45) | P45: =SUM(H45:J45) | Q45: =SUM(K45:M45) | R45: =SUM(B45:M45)
A46: Services | B46: 101.1 | C46: 259.71 | D46: 232.43 | E46: 208.51 | F46: 209.06 | G46: 205.67 | H46: 259.86 | I46: 179.98 | J46: 277.29 | K46: 135.78 | L46: 244.91 | M46: 342.99 | N46: =SUM(B46:D46) | O46: =SUM(E46:G46) | P46: =SUM(H46:J46) | Q46: =SUM(K46:M46) | R46: =SUM(B46:M46)
A47: Revenue | B47: =B44+B45+B46 | C47: =C44+C45+C46 | D47: =D44+D45+D46 | E47: =E44+E45+E46 | F47: =F44+F45+F46 | G47: =G44+G45+G46 | H47: =H44+H45+H46 | I47: =I44+I45+I46 | ... M47: =M44+M45+M46 | N47: =SUM(B47:D47) | O47: =SUM(E47:G47) | P47: =SUM(H47:J47) | Q47: =SUM(K47:M47) | R47: =SUM(B47:M47)
A49: Cost of Revenue
...

Sheet Functional P&L Summary - Jan 25
A1: Keystone BenefitTech, Inc. | E1: Last Updated: 2026-02-28
A2: Functional P&L Summary — January 2025
A4: Line Item | B4: iGO | C4: Affirm | D4: InsureSight | E4: US
A5: Revenue
A6: Subscription | B6: ='Functional P&L - Monthly Trend'!B8 | C6: ='Functional P&L - Monthly Trend'!B44 | D6: ='Functional P&L - Monthly Trend'!B80 | E6: =SUM(B6:D6)
A7: Transactions | B7: ='Functional P&L - Monthly Trend'!B9 | C7: ='Functional P&L - Monthly Trend'!B45 | D7: ='Functional P&L - Monthly Trend'!B81 | E7: =SUM(B7:D7)
A8: Services | B8: ='Functional P&L - Monthly Trend'!B10 | C8: ='Functional P&L - Monthly Trend'!B46 | D8: ='Functional P&L - Monthly Trend'!B82 | E8: =SUM(B8:D8)
A9: Revenue | B9: ='Functional P&L - Monthly Trend'!B11 | C9: ='Functional P&L - Monthly Trend'!B47 | D9: ='Functional P&L - Monthly Trend'!B83 | E9: =SUM(B9:D9)
A11: Cost of Revenue
A12: NetOps | B12: ='Functional P&L - Monthly Trend'!B14 | C12: ='Functional P&L - Monthly Trend'!B50 | D12: ='Functional P&L - Monthly Trend'!B86 | E12: =SUM(B12:D12)
A13: Security | B13: ='Functional P&L - Monthly Trend'!B15 | C13: ='Functional P&L - Monthly Trend'!B51 | D13: ='Functional P&L - Monthly Trend'!B87 | E13: =SUM(B13:D13)
A14: Support | B14: ='Functional P&L - Monthly Trend'!B16 | C14: ='Functional P&L - Monthly Trend'!B52 | D14: ='Functional P&L - Monthly Trend'!B88 | E14: =SUM(B14:D14)
A15: Partners | B15: ='Functional P&L - Monthly Trend'!B17 | C15: ='Functional P&L - Monthly Trend'!B53 | D15: ='Functional P&L - Monthly Trend'!B89 | E15: =SUM(B15:D15)
A16: Content | B16: ='Functional P&L - Monthly Trend'!B18 | C16: ='Functional P&L - Monthly Trend'!B54 | D16: ='Functional P&L - Monthly Trend'!B90 | E16: =SUM(B16:D16)
A17: Cost of Subscription | B17: ='Functional P&L - Monthly Trend'!B19 | C17: ='Functional P&L - Monthly Trend'!B55 | D17: ='Functional P&L - Monthly Trend'!B91 | E17: =SUM(B17:D17)
A18: Cost of Services | B18: ='Functional P&L - Monthly Trend'!B20 | C18: ='Functional P&L - Monthly Trend'!B56 | D18: ='Functional P&L - Monthly Trend'!B92 | E18: =SUM(B18:D18)
A19: Cost of Revenue | B19: ='Functional P&L - Monthly Trend'!B21 | C19: ='Functional P&L - Monthly Trend'!B57 | D19: ='Functional P&L - Monthly Trend'!B93 | E19: =SUM(B19:D19)
A21: Subscriptions Contribution | B21: ='Functional P&L - Monthly Trend'!B23 | C21: ='Functional P&L - Monthly Trend'!B59 | D21: ='Functional P&L - Monthly Trend'!B95 | E21: =SUM(B21:D21)
A22: Services Contribution | B22: ='Functional P&L - Monthly Trend'!B24 | C22: ='Functional P&L - Monthly Trend'!B60 | D22: ='Functional P&L - Monthly Trend'!B96 | E22: =SUM(B22:D22)
A23: Contribution Margin | B23: ='Functional P&L - Monthly Trend'!B25 | C23: ='Functional P&L - Monthly Trend'!B61 | D23: ='Functional P&L - Monthly Trend'!B97 | E23: =SUM(B23:D23)
A24: D&A | B24: ='Functional P&L - Monthly Trend'!B26 | C24: ='Functional P&L - Monthly Trend'!B62 | D24: ='Functional P&L - Monthly Trend'!B98 | E24: =SUM(B24:D24)
A25: Contribution Margin GAAP | B25: ='Functional P&L - Monthly Trend'!B27 | C25: ='Functional P&L - Monthly Trend'!B63 | D25: ='Functional P&L - Monthly Trend'!B99 | E25: =SUM(B25:D25)
A26: Subscription Margin % | B26: ='Functional P&L - Monthly Trend'!B28 | C26: ='Functional P&L - Monthly Trend'!B64 | D26: ='Functional P&L - Monthly Trend'!B100 | E26: =IFERROR(E21/E6,0)
A27: Services Margin % | B27: ='Functional P&L - Monthly Trend'!B29 | C27: ='Functional P&L - Monthly Trend'!B65 | D27: ='Functional P&L - Monthly Trend'!B101 | E27: =IFERROR(E22/E8,0)
A28: Total Margin % | B28: ='Functional P&L - Monthly Trend'!B30 | C28: ='Functional P&L - Monthly Trend'!B66 | D28: ='Functional P&L - Monthly Trend'!B102 | E28: =IFERROR(E23/E9,0)
A30: R&D
A31: R&D (includes Cap Software) | B31: ='Functional P&L - Monthly Trend'!B33 | C31: ='Functional P&L - Monthly Trend'!B69 | D31: ='Functional P&L - Monthly Trend'!B105 | E31: =SUM(B31:D31)
A32: Research & Development | B32: ='Functional P&L - Monthly Trend'!B34 | C32: ='Functional P&L - Monthly Trend'!B70 | D32: ='Functional P&L - Monthly Trend'!B106 | E32: =SUM(B32:D32)
A33: Capitalized R&D | B33: ='Functional P&L - Monthly Trend'!B35 | C33: ='Functional P&L - Monthly Trend'!B71 | D33: ='Functional P&L - Monthly Trend'!B107 | E33: =SUM(B33:D33)
A34: Product Management | B34: ='Functional P&L - Monthly Trend'!B36 | C34: ='Functional P&L - Monthly Trend'!B72 | D34: ='Functional P&L - Monthly Trend'!B108 | E34: =SUM(B34:D34)
A36: Contribution Margin + R&D $ | B36: ='Functional P&L - Monthly Trend'!B38 | C36: ='Functional P&L - Monthly Trend'!B74 | D36: ='Functional P&L - Monthly Trend'!B110 | E36: =SUM(B36:D36)
A37: Contribution Margin + R&D % | B37: ='Functional P&L - Monthly Trend'!B39 | C37: ='Functional P&L - Monthly Trend'!B75 | D37: ='Functional P&L - Monthly Trend'!B111 | E37: =IFERROR(E36/E9,0)

Sheet Functional P&L Summary - Feb 25
A1: Keystone BenefitTech, Inc. | E1: Last Updated: 2026-02-28
A2: Functional P&L Summary — February 2025
A4: Line Item | B4: iGO | C4: Affirm | D4: InsureSight | E4: US
A5: Revenue
A6: Subscription | B6: ='Functional P&L - Monthly Trend'!C8 | C6: ='Functional P&L - Monthly Trend'!C44 | D6: ='Functional P&L - Monthly Trend'!C80 | E6: =SUM(B6:D6)
A7: Transactions | B7: ='Functional P&L - Monthly Trend'!C9 | C7: ='Functional P&L - Monthly Trend'!C45 | D7: ='Functional P&L - Monthly Trend'!C81 | E7: =SUM(B7:D7)
A8: Services | B8: ='Functional P&L - Monthly Trend'!C10 | C8: ='Functional P&L - Monthly Trend'!C46 | D8: ='Functional P&L - Monthly Trend'!C82 | E8: =SUM(B8:D8)
A9: Revenue | B9: ='Functional P&L - Monthly Trend'!C11 | C9: ='Functional P&L - Monthly Trend'!C47 | D9: ='Functional P&L - Monthly Trend'!C83 | E9: =SUM(B9:D9)
A11: Cost of Revenue
A12: NetOps | B12: ='Functional P&L - Monthly Trend'!C14 | C12: ='Functional P&L - Monthly Trend'!C50 | D12: ='Functional P&L - Monthly Trend'!C86 | E12: =SUM(B12:D12)
A13: Security | B13: ='Functional P&L - Monthly Trend'!C15 | C13: ='Functional P&L - Monthly Trend'!C51 | D13: ='Functional P&L - Monthly Trend'!C87 | E13: =SUM(B13:D13)
A14: Support | B14: ='Functional P&L - Monthly Trend'!C16 | C14: ='Functional P&L - Monthly Trend'!C52 | D14: ='Functional P&L - Monthly Trend'!C88 | E14: =SUM(B14:D14)
A15: Partners | B15: ='Functional P&L - Monthly Trend'!C17 | C15: ='Functional P&L - Monthly Trend'!C53 | D15: ='Functional P&L - Monthly Trend'!C89 | E15: =SUM(B15:D15)
A16: Content | B16: ='Functional P&L - Monthly Trend'!C18 | C16: ='Functional P&L - Monthly Trend'!C54 | D16: ='Functional P&L - Monthly Trend'!C90 | E16: =SUM(B16:D16)
A17: Cost of Subscription | B17: ='Functional P&L - Monthly Trend'!C19 | C17: ='Functional P&L - Monthly Trend'!C55 | D17: ='Functional P&L - Monthly Trend'!C91 | E17: =SUM(B17:D17)
A18: Cost of Services | B18: ='Functional P&L - Monthly Trend'!C20 | C18: ='Functional P&L - Monthly Trend'!C56 | D18: ='Functional P&L - Monthly Trend'!C92 | E18: =SUM(B18:D18)
A19: Cost of Revenue | B19: ='Functional P&L - Monthly Trend'!C21 | C19: ='Functional P&L - Monthly Trend'!C57 | D19: ='Functional P&L - Monthly Trend'!C93 | E19: =SUM(B19:D19)
A21: Subscriptions Contribution | B21: ='Functional P&L - Monthly Trend'!C23 | C21: ='Functional P&L - Monthly Trend'!C59 | D21: ='Functional P&L - Monthly Trend'!C95 | E21: =SUM(B21:D21)
A22: Services Contribution | B22: ='Functional P&L - Monthly Trend'!C24 | C22: ='Functional P&L - Monthly Trend'!C60 | D22: ='Functional P&L - Monthly Trend'!C96 | E22: =SUM(B22:D22)
A23: Contribution Margin | B23: ='Functional P&L - Monthly Trend'!C25 | C23: ='Functional P&L - Monthly Trend'!C61 | D23: ='Functional P&L - Monthly Trend'!C97 | E23: =SUM(B23:D23)
A24: D&A | B24: ='Functional P&L - Monthly Trend'!C26 | C24: ='Functional P&L - Monthly Trend'!C62 | D24: ='Functional P&L - Monthly Trend'!C98 | E24: =SUM(B24:D24)
A25: Contribution Margin GAAP | B25: ='Functional P&L - Monthly Trend'!C27 | C25: ='Functional P&L - Monthly Trend'!C63 | D25: ='Functional P&L - Monthly Trend'!C99 | E25: =SUM(B25:D25)
A26: Subscription Margin % | B26: ='Functional P&L - Monthly Trend'!C28 | C26: ='Functional P&L - Monthly Trend'!C64 | D26: ='Functional P&L - Monthly Trend'!C100 | E26: =IFERROR(E21/E6,0)
A27: Services Margin % | B27: ='Functional P&L - Monthly Trend'!C29 | C27: ='Functional P&L - Monthly Trend'!C65 | D27: ='Functional P&L - Monthly Trend'!C101 | E27: =IFERROR(E22/E8,0)
A28: Total Margin % | B28: ='Functional P&L - Monthly Trend'!C30 | C28: ='Functional P&L - Monthly Trend'!C66 | D28: ='Functional P&L - Monthly Trend'!C102 | E28: =IFERROR(E23/E9,0)
A30: R&D
A31: R&D (includes Cap Software) | B31: ='Functional P&L - Monthly Trend'!C33 | C31: ='Functional P&L - Monthly Trend'!C69 | D31: ='Functional P&L - Monthly Trend'!C105 | E31: =SUM(B31:D31)
A32: Research & Development | B32: ='Functional P&L - Monthly Trend'!C34 | C32: ='Functional P&L - Monthly Trend'!C70 | D32: ='Functional P&L - Monthly Trend'!C106 | E32: =SUM(B32:D32)
